Workbook

Sheet Summary
A1: 色彩库 | B1: 色号总数 | C1: 完全匹配 | D1: 可能匹配 | E1: 缺图 | F1: 未使用的本地文件
A2: Outre | B2: =COUNTA(Outre!A:A)-1 -> 533 | C2: =COUNTIF(Outre!F:F,"完全匹配") -> 456 | D2: =COUNTIF(Outre!F:F,"可能匹配") -> 34 | E2: =COUNTIF(Outre!F:F,"缺图") -> 43 | F2: =COUNTIF(未使用的本地文件!A:A,A2) -> 995
A3: its a wig | B3: =COUNTA('its a wig'!A:A)-1 -> 172 | C3: =COUNTIF('its a wig'!F:F,"完全匹配") -> 92 | D3: =COUNTIF('its a wig'!F:F,"可能匹配") -> 23 | E3: =COUNTIF('its a wig'!F:F,"缺图") -> 57 | F3: =COUNTIF(未使用的本地文件!A:A,A3) -> 407
A4: SENSATIONNEL | B4: =COUNTA(SENSATIONNEL!A:A)-1 -> 242 | C4: =COUNTIF(SENSATIONNEL!F:F,"完全匹配") -> 165 | D4: =COUNTIF(SENSATIONNEL!F:F,"可能匹配") -> 44 | E4: =COUNTIF(SENSATIONNEL!F:F,"缺图") -> 33 | F4: =COUNTIF(未使用的本地文件!A:A,A4) -> 460
A5: ROYAL IMEX | B5: =COUNTA('ROYAL IMEX'!A:A)-1 -> 38 | C5: =COUNTIF('ROYAL IMEX'!F:F,"完全匹配") -> 25 | D5: =COUNTIF('ROYAL IMEX'!F:F,"可能匹配") -> 5 | E5: =COUNTIF('ROYAL IMEX'!F:F,"缺图") -> 8 | F5: =COUNTIF(未使用的本地文件!A:A,A5) -> 69
A6: Shake-n-go | B6: =COUNTA('Shake-n-go'!A:A)-1 -> 105 | C6: =COUNTIF('Shake-n-go'!F:F,"完全匹配") -> 78 | D6: =COUNTIF('Shake-n-go'!F:F,"可能匹配") -> 18 | E6: =COUNTIF('Shake-n-go'!F:F,"缺图") -> 9 | F6: =COUNTIF(未使用的本地文件!A:A,A6) -> 632
A7: BOBBI BOSS | B7: =COUNTA('BOBBI BOSS'!A:A)-1 -> 86 | C7: =COUNTIF('BOBBI BOSS'!F:F,"完全匹配") -> 27 | D7: =COUNTIF('BOBBI BOSS'!F:F,"可能匹配") -> 14 | E7: =COUNTIF('BOBBI BOSS'!F:F,"缺图") -> 45 | F7: =COUNTIF(未使用的本地文件!A:A,A7) -> 703
A8: 合计 | B8: =SUM(B2:B7) -> 1176 | C8: =SUM(C2:C7) -> 843 | D8: =SUM(D2:D7) -> 138 | E8: =SUM(E2:E7) -> 195 | F8: =SUM(F2:F7) -> 3266
A10: 说明：
A11: · 数据来源：herabeauty.ca 前台 /products.json（仅已发布产品），Type 限 WIG/HAIR/BRAID，option 名为 Color，2026-09-30 抓取。
A12: · 本地文件：D:\resouces\COLOR CHARTS 下各 Vendor 文件夹（HAIR COUTURE 共用 Outre 库）。
A13: · 完全匹配 = 去掉 #、符号、空格后与文件名完全一致；可能匹配 = 缩写/前缀/相似度 ≥75 分，需人工确认；缺图 = 没有可靠候选。
A14: · 建议文件名 = 色号去掉 #，/ 换成 -（上传工具会按该 Vendor 的真实色号列表反查还原）。
A15: · 「确认后的文件（手填）」列留给你填写最终对应的文件，可作为重命名依据。

Sheet Outre
A1: 色号 (variant name) | B1: Vendor | C1: 产品数 | D1: Type | E1: 示例产品 | F1: 状态 | G1: 匹配文件 | H1: 匹配方式/分数 | I1: 其他候选 | J1: 建议文件名 | K1: 确认后的文件（手填）
A2: #1 | B2: OUTRE | C2: 341 | D2: BRAID/WIG/HAIR | E2: https://herabeauty.ca/products/xp-diy11-bohemian-91011 | F2: 完全匹配 | G2: 1.jpg | H2: 完全 | J2: 1.jpg
A3: #1 | B3: HAIR COUTURE | C3: 21 | D3: HAIR/WIG | E3: https://herabeauty.ca/products/duo-water-wave-2x | F3: 完全匹配 | G3: 1.jpg | H3: 完全 | J3: 1.jpg
A4: #116 | B4: HAIR COUTURE | C4: 1 | D4: HAIR | E4: https://herabeauty.ca/products/smart-hair | F4: 缺图 | H4: 最佳 60 | J4: 116.jpg
A5: #12 | B5: OUTRE | C5: 1 | D5: BRAID | E5: https://herabeauty.ca/products/x-pression-ultra-braid-82-inch | F5: 完全匹配 | G5: 12.jpg | H5: 完全 | J5: 12.jpg
A6: #130S | B6: OUTRE | C6: 1 | D6: HAIR | E6: https://herabeauty.ca/products/purple-pack-100-human-hair-yaki | F6: 完全匹配 | G6: 130S.jpg | H6: 完全 | J6: 130S.jpg
A7: #18/24 | B7: HAIR COUTURE | C7: 1 | D7: HAIR | E7: https://herabeauty.ca/products/remy-human-hair-tape-in-extensions-18in | F7: 缺图 | H7: 最佳 53 | J7: 18-24.jpg
A8: #18/24R | B8: HAIR COUTURE | C8: 2 | D8: WIG | E8: https://herabeauty.ca/products/ambience-100-remy-human-hair-natural-top-small | F8: 缺图 | H8: 最佳 48 | J8: 18-24R.jpg
A9: #18/613 | B9: HAIR COUTURE | C9: 1 | D9: HAIR | E9: https://herabeauty.ca/products/100-remy-human-hair-clip-in-extensions | F9: 缺图 | H9: 最佳 60 | J9: 18-613.jpg
A10: #1B | B10: OUTRE | C10: 341 | D10: BRAID/WIG/HAIR | E10: https://herabeauty.ca/products/xp-diy11-bohemian-91011 | F10: 完全匹配 | G10: 1B.jpg | H10: 完全 | J10: 1B.jpg
A11: #1B | B11: HAIR COUTURE | C11: 21 | D11: HAIR/WIG | E11: https://herabeauty.ca/products/duo-water-wave-2x | F11: 完全匹配 | G11: 1B.jpg | H11: 完全 | J11: 1B.jpg
A12: #1B/30 | B12: HAIR COUTURE | C12: 3 | D12: HAIR | E12: https://herabeauty.ca/products/hc-avanti-clip-str | F12: 可能匹配 | G12: C1B_30.jpg | H12: 相似 76 | I12: F1B_30.jpg (76); M1B_30.jpg (76); T1B_30.jpg (76) | J12: 1B-30.jpg
A13: #2 | B13: OUTRE | C13: 323 | D13: BRAID/WIG/HAIR | E13: https://herabeauty.ca/products/xp-diy11-bohemian-91011 | F13: 完全匹配 | G13: 2.jpg | H13: 完全 | J13: 2.jpg
A14: #2 | B14: HAIR COUTURE | C14: 21 | D14: HAIR/WIG | E14: https://herabeauty.ca/products/duo-water-wave-2x | F14: 完全匹配 | G14: 2.jpg | H14: 完全 | J14: 2.jpg
A15: #2/DRS BLONDE TIARA | B15: OUTRE | C15: 1 | D15: WIG | E15: https://herabeauty.ca/products/lace-front-synthetic-wig-14-inch-bess | F15: 完全匹配 | G15: 2_DRS_BLONDE_TIARA.jpg | H15: 完全 | J15: 2-DRS BLONDE TIARA.jpg
A16: #233 | B16: HAIR COUTURE | C16: 1 | D16: HAIR | E16: https://herabeauty.ca/products/smart-hair | F16: 缺图 | H16: 最佳 60 | J16: 233.jpg
A17: #24 | B17: OUTRE | C17: 1 | D17: BRAID | E17: https://herabeauty.ca/products/x-pression-ultra-braid-82-inch | F17: 完全匹配 | G17: 24.jpg | H17: 完全 | J17: 24.jpg
A18: #24/18 | B18: HAIR COUTURE | C18: 1 | D18: HAIR | E18: https://herabeauty.ca/products/100-remy-human-hair-clip-in-extensions | F18: 缺图 | H18: 最佳 53 | J18: 24-18.jpg
A19: #27 | B19: OUTRE | C19: 32 | D19: BRAID/HAIR/WIG | E19: https://herabeauty.ca/products/purple-pack-brazilian-bundle-pre-stretched-dominican-curl-bulk | F19: 完全匹配 | G19: 27.jpg | H19: 完全 | J19: 27.jpg
A20: #27 | B20: HAIR COUTURE | C20: 1 | D20: HAIR | E20: https://herabeauty.ca/products/smart-hair | F20: 完全匹配 | G20: 27.jpg | H20: 完全 | J20: 27.jpg
A21: #27V | B21: OUTRE | C21: 2 | D21: WIG | E21: https://herabeauty.ca/products/synthetic-lace-part-wig-ryan-12 | F21: 完全匹配 | G21: 27V.jpg | H21: 完全 | J21: 27V.jpg
A22: #27＆30＆613 | B22: OUTRE | C22: 1 | D22: BRAID | E22: https://herabeauty.ca/products/pre-stretched-braiding-hair-3x-52in | F22: 完全匹配 | G22: 27_30_613.jpg | H22: 完全 | J22: 27＆30＆613.jpg
A23: #280 | B23: OUTRE | C23: 1 | D23: WIG | E23: https://herabeauty.ca/products/gray-human-hair-wig-for-women-celia | F23: 完全匹配 | G23: 280.jpg | H23: 完全 | J23: 280.jpg
A24: #2T/30 | B24: OUTRE | C24: 2 | D24: WIG | E24: https://herabeauty.ca/products/wigpop-synthetic-full-cap-wig-chrisette | F24: 完全匹配 | G24: 2T_30.jpg | H24: 完全 | J24: 2T-30.jpg
A25: #2T/3027 | B25: OUTRE | C25: 2 | D25: WIG | E25: https://herabeauty.ca/products/pre-braided-lace-frontal-wig-13x4 | F25: 完全匹配 | G25: 2T_3027.jpg | H25: 完全 | J25: 2T-3027.jpg
A26: #2T/425 | B26: OUTRE | C26: 1 | D26: WIG | E26: https://herabeauty.ca/products/wigpop-synthetic-full-cap-wig-chrisette | F26: 完全匹配 | G26: 2T_425.jpg | H26: 完全 | J26: 2T-425.jpg
A27: #2T1/27 | B27: OUTRE | C27: 6 | D27: HAIR | E27: https://herabeauty.ca/products/ponytail-wig-with-bangs-pony-kayla | F27: 完全匹配 | G27: 2T1_27.jpg | H27: 完全 | J27: 2T1-27.jpg
A28: #2T1/27613 | B28: OUTRE | C28: 3 | D28: HAIR | E28: https://herabeauty.ca/products/afro-ponytail-extension-pretty-quick | F28: 完全匹配 | G28: 2T1_27613.jpg | H28: 完全 | J28: 2T1-27613.jpg
A29: #2T1/30 | B29: OUTRE | C29: 19 | D29: HAIR/WIG | E29: https://herabeauty.ca/products/3b-curly-drawstring-ponytail-18-inch | F29: 完全匹配 | G29: 2T1_30.jpg | H29: 完全 | J29: 2T1-30.jpg
A30: #2T1/350 | B30: OUTRE | C30: 2 | D30: HAIR | E30: https://herabeauty.ca/products/3b-curly-drawstring-ponytail-18-inch | F30: 完全匹配 | G30: 2T1_350.jpg | H30: 完全 | J30: 2T1-350.jpg
... A32: #2T1/60 | B32: OUTRE | C32: 1 | D32: HAIR | E32: https://herabeauty.ca/products/afro-puff-ponytail-extension-pretty-quick-1 | F32: 完全匹配 | G32: 2T1_60.jpg | H32: 完全 | J32: 2T1-60.jpg
A33: #2T1/BU | B33: OUTRE | C33: 8 | D33: HAIR | E33: https://herabeauty.ca/products/3b-curly-drawstring-ponytail-18-inch | F33: 可能匹配 | G33: 2T1_BURGUNDY.jpg | H33: 逐段缩写 88 | I33: 2T1B_BLUE.jpg (82); 2T1B_PURPLE.jpg (80); 2T1B_FUCHSIA.jpg (79) | J33: 2T1-BU.jpg
A34: #2T1B/130S | B34: OUTRE | C34: 2 | D34: BRAID | E34: https://herabeauty.ca/products/jumbo-braid-hair-extensions-56-inch | F34: 完全匹配 | G34: 2T1B_130S.jpg | H34: 完全 | J34: 2T1B-130S.jpg
A35: #2T1B/27 | B35: OUTRE | C35: 27 | D35: BRAID | E35: https://herabeauty.ca/products/purple-pack-brazilian-bundle-feather-crochet-hawaiian | F35: 完全匹配 | G35: 2T1B_27.jpg | H35: 完全 | J35: 2T1B-27.jpg
A36: #2T1B/2730 | B36: OUTRE | C36: 3 | D36: BRAID/HAIR | E36: https://herabeauty.ca/products/pre-stretched-braiding-hair-3x-52in | F36: 完全匹配 | G36: 2T1B_2730.jpg | H36: 完全 | J36: 2T1B-2730.jpg
A37: #2T1B/27613 | B37: OUTRE | C37: 1 | D37: BRAID | E37: https://herabeauty.ca/products/pre-stretched-braiding-hair-3x-52in | F37: 完全匹配 | G37: 2T1B_27613.jpg | H37: 完全 | J37: 2T1B-27613.jpg
A38: #2T1B/30 | B38: OUTRE | C38: 30 | D38: BRAID/WIG | E38: https://herabeauty.ca/products/xp-diy11-bohemian-91011 | F38: 完全匹配 | G38: 2T1B_30.jpg | H38: 完全 | J38: 2T1B-30.jpg
A39: #2T1B/33 | B39: OUTRE | C39: 3 | D39: BRAID | E39: https://herabeauty.ca/products/pre-stretched-braiding-hair-42-inch | F39: 完全匹配 | G39: 2T1B_33.jpg | H39: 完全 | J39: 2T1B-33.jpg
A40: #2T1B/350 | B40: OUTRE | C40: 5 | D40: BRAID | E40: https://herabeauty.ca/products/butterfly-locs-hair-extensions-20 | F40: 完全匹配 | G40: 2T1B_350.jpg | H40: 完全 | J40: 2T1B-350.jpg
A41: #2T1B/425 | B41: OUTRE | C41: 6 | D41: BRAID | E41: https://herabeauty.ca/products/xp-t-up-3x-type-4-s-n-frappe-10 | F41: 完全匹配 | G41: 2T1B_425.jpg | H41: 完全 | J41: 2T1B-425.jpg
...

Sheet its a wig
A1: 色号 (variant name) | B1: Vendor | C1: 产品数 | D1: Type | E1: 示例产品 | F1: 状态 | G1: 匹配文件 | H1: 匹配方式/分数 | I1: 其他候选 | J1: 建议文件名 | K1: 确认后的文件（手填）
A2: #1 | B2: IT'S A WIG | C2: 98 | D2: WIG | E2: https://herabeauty.ca/products/bff-tp-mirella | F2: 完全匹配 | G2: 1.jpg | H2: 完全 | J2: 1.jpg
A3: #1B | B3: IT'S A WIG | C3: 99 | D3: WIG | E3: https://herabeauty.ca/products/bff-tp-mirella | F3: 完全匹配 | G3: 1B.jpg | H3: 完全 | J3: 1B.jpg
A4: #2 | B4: IT'S A WIG | C4: 85 | D4: WIG | E4: https://herabeauty.ca/products/bff-tp-mirella | F4: 完全匹配 | G4: 2.jpg | H4: 完全 | J4: 2.jpg
A5: #27 | B5: IT'S A WIG | C5: 12 | D5: WIG | E5: https://herabeauty.ca/products/human-hair-wig-with-bangs-chantel | F5: 完全匹配 | G5: 27.jpg | H5: 完全 | J5: 27.jpg
A6: #280 | B6: IT'S A WIG | C6: 1 | D6: WIG | E6: https://herabeauty.ca/products/100-percent-human-hair-lace-wig-gloria | F6: 完全匹配 | G6: 280.jpg | H6: 完全 | J6: 280.jpg
A7: #3 | B7: IT'S A WIG | C7: 4 | D7: WIG | E7: https://herabeauty.ca/products/wig-fw-britty | F7: 缺图 | H7: 最佳 53 | J7: 3.jpg
A8: #30 | B8: IT'S A WIG | C8: 4 | D8: WIG | E8: https://herabeauty.ca/products/13x4-lace-front-wig-straight-22 | F8: 完全匹配 | G8: 30.jpg | H8: 完全 | J8: 30.jpg
A9: #350 | B9: IT'S A WIG | C9: 6 | D9: WIG | E9: https://herabeauty.ca/products/human-hair-wig-with-bangs-chantel | F9: 完全匹配 | G9: 350.jpg | H9: 完全 | J9: 350.jpg
A10: #3S/HONEY GOLD | B10: IT'S A WIG | C10: 2 | D10: WIG | E10: https://herabeauty.ca/products/hd-lace-front-wig-becca | F10: 完全匹配 | G10: 3S_HONEY_GOLD.jpg | H10: 完全 | J10: 3S-HONEY GOLD.jpg
A11: #3T CYBER PURPLE | B11: IT'S A WIG | C11: 1 | D11: WIG | E11: https://herabeauty.ca/products/synthetic-hd-lace-front-wig-julietta | F11: 缺图 | H11: 最佳 56 | J11: 3T CYBER PURPLE.jpg
A12: #3T PINK BLUSH | B12: IT'S A WIG | C12: 1 | D12: WIG | E12: https://herabeauty.ca/products/synthetic-hd-lace-front-wig-julietta | F12: 缺图 | H12: 最佳 51 | J12: 3T PINK BLUSH.jpg
A13: #3T/HM GREY | B13: IT'S A WIG | C13: 5 | D13: WIG | E13: https://herabeauty.ca/products/synthetic-full-cap-wig-denisa | F13: 缺图 | H13: 最佳 57 | J13: 3T-HM GREY.jpg
A14: #3T5004 | B14: IT'S A WIG | C14: 1 | D14: WIG | E14: https://herabeauty.ca/products/synthetic-curly-half-wig-novia | F14: 完全匹配 | G14: 3T5004.jpg | H14: 完全 | J14: 3T5004.jpg
A15: #3TT27/613 | B15: IT'S A WIG | C15: 1 | D15: WIG | E15: https://herabeauty.ca/products/synthetic-full-wig-for-women-q-nory | F15: 完全匹配 | G15: 3TT27_613.jpg | H15: 完全 | J15: 3TT27-613.jpg
A16: #4 | B16: IT'S A WIG | C16: 6 | D16: WIG | E16: https://herabeauty.ca/products/its-a-wig-synthetic-half-wig-aggie | F16: 完全匹配 | G16: 4.jpg | H16: 完全 | J16: 4.jpg
A17: #613 | B17: IT'S A WIG | C17: 12 | D17: WIG | E17: https://herabeauty.ca/products/synthetic-13x6-lace-frontal-wig-divine | F17: 完全匹配 | G17: 613.jpg | H17: 完全 | J17: 613.jpg
A18: #99J | B18: IT'S A WIG | C18: 6 | D18: WIG | E18: https://herabeauty.ca/products/full-cap-simone | F18: 完全匹配 | G18: 99J.jpg | H18: 完全 | J18: 99J.jpg
A19: #BALAYAGE AUTUMN BROWN | B19: IT'S A WIG | C19: 1 | D19: WIG | E19: https://herabeauty.ca/products/4x4-lace-front-boho-box-wig | F19: 缺图 | H19: 最佳 62 | J19: BALAYAGE AUTUMN BROWN.jpg
A20: #BALAYAGE CARAMEL | B20: IT'S A WIG | C20: 7 | D20: WIG | E20: https://herabeauty.ca/products/wig-fw-bang-kimony | F20: 缺图 | H20: 最佳 57 | J20: BALAYAGE CARAMEL.jpg
A21: #BALAYAGE CHAMPAGNE | B21: IT'S A WIG | C21: 3 | D21: WIG | E21: https://herabeauty.ca/products/headband-wig-curly-glow | F21: 缺图 | H21: 最佳 58 | J21: BALAYAGE CHAMPAGNE.jpg
A22: #BALAYAGE CHOCOLATE | B22: IT'S A WIG | C22: 2 | D22: WIG | E22: https://herabeauty.ca/products/bff-lace-dannie | F22: 缺图 | H22: 最佳 52 | J22: BALAYAGE CHOCOLATE.jpg
A23: #BALAYAGE COOL BLONDE | B23: IT'S A WIG | C23: 3 | D23: WIG | E23: https://herabeauty.ca/products/bff-lace-dannie | F23: 缺图 | H23: 最佳 55 | J23: BALAYAGE COOL BLONDE.jpg
A24: #BALAYAGE COPPER | B24: IT'S A WIG | C24: 1 | D24: WIG | E24: https://herabeauty.ca/products/4x4-lace-front-boho-box-wig | F24: 可能匹配 | G24: BALAYAGE_COPPER_BROWN.jpg | H24: 缩写 85 | J24: BALAYAGE COPPER.jpg
A25: #BALAYAGE COPPER ESPRESSO | B25: IT'S A WIG | C25: 5 | D25: WIG | E25: https://herabeauty.ca/products/illuze-lace-13x4-loretta | F25: 缺图 | H25: 最佳 66 | J25: BALAYAGE COPPER ESPRESSO.jpg
A26: #BALAYAGE FANCY BRONZE | B26: IT'S A WIG | C26: 6 | D26: WIG | E26: https://herabeauty.ca/products/wig-fw-bang-kimony | F26: 缺图 | H26: 最佳 58 | J26: BALAYAGE FANCY BRONZE.jpg
A27: #BALAYAGE RALLY RED | B27: IT'S A WIG | C27: 1 | D27: WIG | E27: https://herabeauty.ca/products/nutique-glenda-18-inch-lace-front-wig | F27: 缺图 | H27: 最佳 60 | J27: BALAYAGE RALLY RED.jpg
A28: #BALAYAGE SUNDOWN CARAMEL | B28: IT'S A WIG | C28: 1 | D28: WIG | E28: https://herabeauty.ca/products/wig-lace-anett | F28: 缺图 | H28: 最佳 46 | J28: BALAYAGE SUNDOWN CARAMEL.jpg
A29: #BURG | B29: IT'S A WIG | C29: 6 | D29: WIG | E29: https://herabeauty.ca/products/13x4-lace-front-wig-straight-22 | F29: 完全匹配 | G29: BURG.jpg | H29: 完全 | J29: BURG.jpg
A30: #BURGUNDY | B30: IT'S A WIG | C30: 6 | D30: WIG | E30: https://herabeauty.ca/products/bbf-lace-front-best | F30: 可能匹配 | G30: BURG.jpg | H30: 逐段缩写 88 | J30: BURGUNDY.jpg
A31: #BURGUNDY ANGEL | B31: IT'S A WIG | C31: 8 | D31: WIG | E31: https://herabeauty.ca/products/bff-tp-mirella | F31: 缺图 | H31: 最佳 52 | J31: BURGUNDY ANGEL.jpg
A32: #BUTTER SCOTCH MELT | B32: IT'S A WIG | C32: 1 | D32: WIG | E32: https://herabeauty.ca/products/wig-fw-britty | F32: 可能匹配 | G32: BUTTERSCOTCH.jpg | H32: 缩写 85 | J32: BUTTER SCOTCH MELT.jpg
A33: #BUTTERSCOTCH | B33: IT'S A WIG | C33: 3 | D33: WIG | E33: https://herabeauty.ca/products/bbf-lace-front-best | F33: 完全匹配 | G33: BUTTERSCOTCH.jpg | H33: 完全 | J33: BUTTERSCOTCH.jpg
A34: #CARAMEL | B34: IT'S A WIG | C34: 3 | D34: WIG | E34: https://herabeauty.ca/products/bbf-lace-front-best | F34: 缺图 | H34: 最佳 74 | I34: NAT_CARAMEL.jpg (70); NTT_CARAMEL.jpg (70); 3NTT_CARAMEL.jpg (60) | J34: CARAMEL.jpg
A35: #CARAMEL DRIZZLE | B35: IT'S A WIG | C35: 2 | D35: WIG | E35: https://herabeauty.ca/products/illuze-string-up-360-13x4-lace-wig-billie | F35: 缺图 | H35: 最佳 53 | J35: CARAMEL DRIZZLE.jpg
A36: #CARROT COPPER | B36: IT'S A WIG | C36: 1 | D36: WIG | E36: https://herabeauty.ca/products/nutique-illuze-full-lace-wig | F36: 缺图 | H36: 最佳 65 | J36: CARROT COPPER.jpg
A37: #CHARCOAL GREY | B37: IT'S A WIG | C37: 1 | D37: WIG | E37: https://herabeauty.ca/products/full-cap-simone | F37: 完全匹配 | G37: CHARCOAL_GREY.jpg | H37: 完全 | J37: CHARCOAL GREY.jpg
A38: #CHERRY COLA | B38: IT'S A WIG | C38: 2 | D38: WIG | E38: https://herabeauty.ca/products/illuze-string-up-360-13x4-lace-wig-billie | F38: 缺图 | H38: 最佳 54 | J38: CHERRY COLA.jpg
A39: #CHESTNUT BROWN | B39: IT'S A WIG | C39: 3 | D39: WIG | E39: https://herabeauty.ca/products/bff-tp-mirella | F39: 完全匹配 | G39: CHESTNUT_BROWN.jpg | H39: 完全 | J39: CHESTNUT BROWN.jpg
A40: #CHIC GREY | B40: IT'S A WIG | C40: 4 | D40: WIG | E40: https://herabeauty.ca/products/premium-synthetic-wig-cassidy | F40: 缺图 | H40: 最佳 60 | J40: CHIC GREY.jpg
...

Sheet SENSATIONNEL
A1: 色号 (variant name) | B1: Vendor | C1: 产品数 | D1: Type | E1: 示例产品 | F1: 状态 | G1: 匹配文件 | H1: 匹配方式/分数 | I1: 其他候选 | J1: 建议文件名 | K1: 确认后的文件（手填）
A2: #1 | B2: SENSATIONNEL | C2: 200 | D2: WIG/BRAID/HAIR | E2: https://herabeauty.ca/products/wig-lace-13x5-water-deep-16 | F2: 完全匹配 | G2: 1.jpg | H2: 完全 | J2: 1.jpg
A3: #1B | B3: SENSATIONNEL | C3: 201 | D3: WIG/BRAID/HAIR | E3: https://herabeauty.ca/products/wig-lace-13x5-water-deep-16 | F3: 完全匹配 | G3: 1B.jpg | H3: 完全 | J3: 1B.jpg
A4: #2 | B4: SENSATIONNEL | C4: 192 | D4: WIG/BRAID/HAIR | E4: https://herabeauty.ca/products/wig-lace-13x5-water-deep-16 | F4: 完全匹配 | G4: 2.jpg | H4: 完全 | J4: 2.jpg
A5: #27 | B5: SENSATIONNEL | C5: 19 | D5: BRAID/HAIR | E5: https://herabeauty.ca/products/ruwa-loc-extension | F5: 完全匹配 | G5: 27.jpg | H5: 完全 | J5: 27.jpg
A6: #30 | B6: SENSATIONNEL | C6: 27 | D6: BRAID/HAIR | E6: https://herabeauty.ca/products/premium-too-feather-crochet-burmese-curl | F6: 完全匹配 | G6: 30.jpg | H6: 完全 | J6: 30.jpg
A7: #33 | B7: SENSATIONNEL | C7: 1 | D7: HAIR | E7: https://herabeauty.ca/products/premium-now-100-human-hair-yaki | F7: 完全匹配 | G7: 33.jpg | H7: 完全 | J7: 33.jpg
A8: #3T2/27/613 | B8: SENSATIONNEL | C8: 1 | D8: BRAID | E8: https://herabeauty.ca/products/pre-stretched-braiding-hair-58-inch | F8: 完全匹配 | G8: 3T2-27-613.jpg | H8: 完全 | J8: 3T2-27-613.jpg
A9: #3T2/30/27 | B9: SENSATIONNEL | C9: 1 | D9: BRAID | E9: https://herabeauty.ca/products/pre-stretched-braiding-hair-58-inch | F9: 完全匹配 | G9: 3T2-30-27.jpg | H9: 完全 | J9: 3T2-30-27.jpg
A10: #4 | B10: SENSATIONNEL | C10: 78 | D10: BRAID/HAIR/WIG | E10: https://herabeauty.ca/products/premium-too-feather-crochet-burmese-curl | F10: 完全匹配 | G10: 4.jpg | H10: 完全 | J10: 4.jpg
A11: #613 | B11: SENSATIONNEL | C11: 36 | D11: BRAID/HAIR/WIG | E11: https://herabeauty.ca/products/lulutress-passion-twist | F11: 完全匹配 | G11: 613.jpg | H11: 完全 | J11: 613.jpg
A12: #99J | B12: SENSATIONNEL | C12: 20 | D12: BRAID/HAIR/WIG | E12: https://herabeauty.ca/products/lulutress-passion-twist | F12: 缺图 | H12: 最佳 60 | J12: 99J.jpg
A13: #APPLE RED | B13: SENSATIONNEL | C13: 2 | D13: WIG | E13: https://herabeauty.ca/products/shear-muse-takeisha-26 | F13: 可能匹配 | G13: APPLE-RED-FIRE-RED-NRED.jpg | H13: 缩写 78 | I13: Copper-Red.jpg (60); Apple-Red-1.jpg (60) | J13: APPLE RED.jpg
A14: #APPLERED/FIRERED/NRED | B14: SENSATIONNEL | C14: 1 | D14: BRAID | E14: https://herabeauty.ca/products/pre-stretched-braiding-hair-58-inch | F14: 完全匹配 | G14: APPLE-RED-FIRE-RED-NRED.jpg | H14: 完全 | J14: APPLERED-FIRERED-NRED.jpg
A15: #ASH PEACH BLONDE | B15: SENSATIONNEL | C15: 4 | D15: WIG | E15: https://herabeauty.ca/products/glamzy-lace-crown-full-wig-cherry-22 | F15: 缺图 | H15: 最佳 65 | I15: super-blonde.jpg (61); ASHBLONDE-2.jpg (60); ASHPEACHBLONDE-1.jpg (60) | J15: ASH PEACH BLONDE.jpg
A16: #ASHY BLUE | B16: SENSATIONNEL | C16: 1 | D16: WIG | E16: https://herabeauty.ca/products/dashly-lace-front-wig-unit-55 | F16: 缺图 | H16: 最佳 64 | J16: ASHY BLUE.jpg
A17: #AUTUMN | B17: SENSATIONNEL | C17: 1 | D17: WIG | E17: https://herabeauty.ca/products/human-hair-full-cap-wig-fab-fringe | F17: 完全匹配 | G17: autumn.jpg | H17: 完全 | J17: AUTUMN.jpg
A18: #BALAYAGE ASHBLONDE | B18: SENSATIONNEL | C18: 3 | D18: WIG | E18: https://herabeauty.ca/products/chic-bob-wig-for-women-unit-8 | F18: 完全匹配 | G18: BALAYAGE-ASHBLONDE.jpg | H18: 完全 | J18: BALAYAGE ASHBLONDE.jpg
A19: #BALAYAGE AUBURN | B19: SENSATIONNEL | C19: 3 | D19: WIG/HAIR | E19: https://herabeauty.ca/products/glamzy-lace-crown-full-wig-zoeey-22 | F19: 缺图 | H19: 最佳 68 | I19: BALAYAGE-ASHBLONDE.jpg (60); Balayage-Auburn-1.jpg (60) | J19: BALAYAGE AUBURN.jpg
A20: #BALAYAGE BLONDE | B20: SENSATIONNEL | C20: 1 | D20: WIG | E20: https://herabeauty.ca/products/butta-lace-crimp-vibe | F20: 可能匹配 | G20: BALAYAGE-ASHBLONDE.jpg | H20: 缩写 86 | I20: Balayage-Buttery-Blonde.jpg (83); Balayage-Vanilla-Blonde.jpg (83); FLAMBOYAGEBLONDE.jpg (68) | J20: BALAYAGE BLONDE.jpg
A21: #BALAYAGE CARAMEL | B21: SENSATIONNEL | C21: 17 | D21: WIG | E21: https://herabeauty.ca/products/dashly-full-cap-unit-27 | F21: 完全匹配 | G21: Balayage-Caramel.jpg | H21: 完全 | J21: BALAYAGE CARAMEL.jpg
A22: #BALAYAGE CHARCOAL ROSE | B22: SENSATIONNEL | C22: 1 | D22: WIG | E22: https://herabeauty.ca/products/hexdoll-raven | F22: 缺图 | H22: 最佳 64 | I22: Balayage-Caramel.jpg (63) | J22: BALAYAGE CHARCOAL ROSE.jpg
A23: #BALAYAGE CHOCOLATE | B23: SENSATIONNEL | C23: 24 | D23: WIG/HAIR | E23: https://herabeauty.ca/products/wig-lace-13x5-water-deep-16 | F23: 完全匹配 | G23: Balayage-Chocolate.jpg | H23: 完全 | J23: BALAYAGE CHOCOLATE.jpg
A24: #BALAYAGE COPPER | B24: SENSATIONNEL | C24: 1 | D24: WIG | E24: https://herabeauty.ca/products/lace-front-wig-with-90s-bangs | F24: 完全匹配 | G24: Balayage-Copper.jpg | H24: 完全 | J24: BALAYAGE COPPER.jpg
A25: #BALAYAGE CRAMEL | B25: SENSATIONNEL | C25: 1 | D25: WIG | E25: https://herabeauty.ca/products/cloud-9-hd-lace-wig-elena | F25: 可能匹配 | G25: Balayage-Caramel.jpg | H25: 缩写 89 | I25: FLAMBOYAGECARAMEL.jpg (66); Balayage-Copper.jpg (61); Balayage-Chocolate.jpg (60) | J25: BALAYAGE CRAMEL.jpg
A26: #BALAYAGE GOLD | B26: SENSATIONNEL | C26: 17 | D26: WIG | E26: https://herabeauty.ca/products/glamzy-lace-crown-full-wig-zoeey-22 | F26: 完全匹配 | G26: Balayage-Gold.jpg | H26: 完全 | J26: BALAYAGE GOLD.jpg
A27: #BALAYAGE HAZELNUT | B27: SENSATIONNEL | C27: 16 | D27: WIG | E27: https://herabeauty.ca/products/wig-hw-up-down-27 | F27: 缺图 | H27: 最佳 60 | I27: Balayage-Hazelnut-1.jpg (60) | J27: BALAYAGE HAZELNUT.jpg
A28: #BALAYAGE LATTE | B28: SENSATIONNEL | C28: 2 | D28: WIG | E28: https://herabeauty.ca/products/butta-lace-unit-29-wig | F28: 缺图 | H28: 最佳 68 | I28: Balayage-Gold.jpg (61); Balayage-Latte-1.jpg (60) | J28: BALAYAGE LATTE.jpg
A29: #BALAYAGE LIGHTASHBLONDE | B29: SENSATIONNEL | C29: 1 | D29: WIG | E29: https://herabeauty.ca/products/dashly-unit-21-wig | F29: 可能匹配 | G29: BALAYAGE-ASHBLONDE.jpg | H29: 缩写 85 | I29: Balayage-Vanilla-Blonde.jpg (63); FLAMBOYAGEASHBLONDE.jpg (62); Balayage-Blonde-1.jpg (60) | J29: BALAYAGE LIGHTASHBLONDE.jpg
A30: #BALAYAGE MOCHA | B30: SENSATIONNEL | C30: 19 | D30: WIG | E30: https://herabeauty.ca/products/wig-lace-13x5-water-deep-16 | F30: 缺图 | H30: 最佳 67 | I30: Balayage-Chocolate.jpg (62); Balayage-Gold.jpg (61); Balayage-Macchiato-1.jpg (60) | J30: BALAYAGE MOCHA.jpg
A31: #BALAYAGE MUSHROOM BLONDE | B31: SENSATIONNEL | C31: 1 | D31: WIG | E31: https://herabeauty.ca/products/shear-muse-mystic-krush-esme | F31: 缺图 | H31: 最佳 70 | I31: Balayage-Buttery-Blonde.jpg (63); Balayage-Blonde-1.jpg (60); Balayage-Medium-Blonde-1.jpg (60) | J31: BALAYAGE MUSHROOM BLONDE.jpg
A32: #BALAYAGE MUSHROOM BROWN | B32: SENSATIONNEL | C32: 1 | D32: WIG | E32: https://herabeauty.ca/products/shear-muse-mystic-krush-esme | F32: 缺图 | H32: 最佳 65 | J32: BALAYAGE MUSHROOM BROWN.jpg
A33: #BALAYAGE OLIVE BEIGE | B33: SENSATIONNEL | C33: 1 | D33: WIG | E33: https://herabeauty.ca/products/shear-muse-mystic-krush-esme | F33: 缺图 | H33: 最佳 61 | J33: BALAYAGE OLIVE BEIGE.jpg
A34: #BALAYAGE PLATINUM | B34: SENSATIONNEL | C34: 3 | D34: WIG | E34: https://herabeauty.ca/products/butta-lace-wig-pre-cut-unit-15 | F34: 缺图 | H34: 最佳 60 | I34: Balayage-Platinum-1.jpg (60) | J34: BALAYAGE PLATINUM.jpg
A35: #BALAYAGE SMOKY CHARCOAL | B35: SENSATIONNEL | C35: 1 | D35: WIG | E35: https://herabeauty.ca/products/shear-muse-mystic-krush-esme | F35: 缺图 | H35: 最佳 65 | I35: Balayage-Caramel.jpg (61) | J35: BALAYAGE SMOKY CHARCOAL.jpg
A36: #BALAYAGE SMOKY ESPRESSO | B36: SENSATIONNEL | C36: 1 | D36: WIG | E36: https://herabeauty.ca/products/shear-muse-mystic-krush-esme | F36: 缺图 | H36: 最佳 65 | J36: BALAYAGE SMOKY ESPRESSO.jpg
A37: #BALAYAGE SUNKISSED | B37: SENSATIONNEL | C37: 6 | D37: WIG | E37: https://herabeauty.ca/products/dashly-full-cap-unit-27 | F37: 缺图 | H37: 最佳 60 | J37: BALAYAGE SUNKISSED.jpg
A38: #BEIGE ASH BLONDE | B38: SENSATIONNEL | C38: 2 | D38: WIG | E38: https://herabeauty.ca/products/shear-muse-gold-krush-lanisha | F38: 可能匹配 | G38: BEIGEBLONDE.jpg | H38: 缩写 86 | I38: BALAYAGE-ASHBLONDE.jpg (66); BLEACHBLONDE.jpg (65); FLAMBOYAGEASHBLONDE.jpg (62) | J38: BEIGE ASH BLONDE.jpg
A39: #BEIGE BLONDE | B39: SENSATIONNEL | C39: 6 | D39: WIG | E39: https://herabeauty.ca/products/wig-lace-13x5-water-deep-16 | F39: 完全匹配 | G39: BEIGEBLONDE.jpg | H39: 完全 | J39: BEIGE BLONDE.jpg
A40: #BURGUNDY | B40: SENSATIONNEL | C40: 15 | D40: HAIR/BRAID/WIG | E40: https://herabeauty.ca/products/sensationnel-empire-100-human-hair-yaki | F40: 可能匹配 | G40: BG.jpg | H40: 逐段缩写 88 | I40: burgundyWine.jpg (88); mburgundy.jpg (80); OM-Burgundy.jpg (76) | J40: BURGUNDY.jpg
...

Sheet ROYAL IMEX
A1: 色号 (variant name) | B1: Vendor | C1: 产品数 | D1: Type | E1: 示例产品 | F1: 状态 | G1: 匹配文件 | H1: 匹配方式/分数 | I1: 其他候选 | J1: 建议文件名 | K1: 确认后的文件（手填）
A2: #1 | B2: ROYAL IMEX | C2: 44 | D2: BRAID/HAIR | E2: https://herabeauty.ca/products/royal-6x-3d-fc-tresse-40 | F2: 完全匹配 | G2: 1.jpg | H2: 完全 | J2: 1.jpg
A3: #1B | B3: ROYAL IMEX | C3: 46 | D3: BRAID/HAIR | E3: https://herabeauty.ca/products/royal-6x-3d-fc-tresse-40 | F3: 完全匹配 | G3: 1B.jpg | H3: 完全 | J3: 1B.jpg
A4: #1B/30 | B4: ROYAL IMEX | C4: 1 | D4: BRAID | E4: https://herabeauty.ca/products/pre-stretched-braiding-hair-zury-acv-48 | F4: 缺图 | H4: 最佳 68 | J4: 1B-30.jpg
A5: #2 | B5: ROYAL IMEX | C5: 34 | D5: BRAID/HAIR | E5: https://herabeauty.ca/products/royal-6x-3d-fc-tresse-40 | F5: 完全匹配 | G5: 2.jpg | H5: 完全 | J5: 2.jpg
A6: #22 | B6: ROYAL IMEX | C6: 1 | D6: HAIR | E6: https://herabeauty.ca/products/18-inch-clip-in-hair-extensions-royal-imex | F6: 缺图 | H6: 最佳 68 | J6: 22.jpg
A7: #27 | B7: ROYAL IMEX | C7: 7 | D7: BRAID | E7: https://herabeauty.ca/products/royal-ultra-deep-bulk | F7: 完全匹配 | G7: 27.jpg | H7: 完全 | J7: 27.jpg
A8: #27/30/613 | B8: ROYAL IMEX | C8: 2 | D8: HAIR | E8: https://herabeauty.ca/products/nd-clip-natural-yaky-18 | F8: 缺图 | H8: 最佳 57 | J8: 27-30-613.jpg
A9: #30 | B9: ROYAL IMEX | C9: 7 | D9: BRAID/HAIR | E9: https://herabeauty.ca/products/royal-ultra-deep-bulk | F9: 完全匹配 | G9: 30.jpg | H9: 完全 | J9: 30.jpg
A10: #350 | B10: ROYAL IMEX | C10: 4 | D10: BRAID | E10: https://herabeauty.ca/products/royal-ultra-deep-bulk | F10: 缺图 | H10: 最佳 60 | J10: 350.jpg
A11: #4 | B11: ROYAL IMEX | C11: 31 | D11: BRAID/HAIR | E11: https://herabeauty.ca/products/royal-6x-3d-fc-tresse-40 | F11: 完全匹配 | G11: 4.jpg | H11: 完全 | J11: 4.jpg
A12: #613 | B12: ROYAL IMEX | C12: 3 | D12: HAIR | E12: https://herabeauty.ca/products/lurex-str-clip-9pcs | F12: 完全匹配 | G12: 613.jpg | H12: 完全 | J12: 613.jpg
A13: #99J | B13: ROYAL IMEX | C13: 3 | D13: HAIR/BRAID | E13: https://herabeauty.ca/products/lurex-str-clip-9pcs | F13: 完全匹配 | G13: 99J.jpg | H13: 完全 | J13: 99J.jpg
A14: #F14/22 | B14: ROYAL IMEX | C14: 2 | D14: HAIR | E14: https://herabeauty.ca/products/18-inch-clip-in-hair-extensions-royal-imex | F14: 完全匹配 | G14: F14_22.jpg | H14: 完全 | J14: F14-22.jpg
A15: #F14/27/613 | B15: ROYAL IMEX | C15: 1 | D15: HAIR | E15: https://herabeauty.ca/products/18-inch-clip-in-hair-extensions-royal-imex | F15: 缺图 | H15: 最佳 57 | J15: F14-27-613.jpg
A16: #F18/22 | B16: ROYAL IMEX | C16: 1 | D16: HAIR | E16: https://herabeauty.ca/products/lurex-str-clip-9pcs | F16: 完全匹配 | G16: F18_22.jpg | H16: 完全 | J16: F18-22.jpg
A17: #F18/613 | B17: ROYAL IMEX | C17: 1 | D17: HAIR | E17: https://herabeauty.ca/products/18-inch-clip-in-hair-extensions-royal-imex | F17: 完全匹配 | G17: F18_613.jpg | H17: 完全 | J17: F18-613.jpg
A18: #F27/16/613 | B18: ROYAL IMEX | C18: 1 | D18: HAIR | E18: https://herabeauty.ca/products/lurex-str-clip-9pcs | F18: 缺图 | H18: 最佳 60 | J18: F27-16-613.jpg
A19: #F4/27 | B19: ROYAL IMEX | C19: 4 | D19: HAIR | E19: https://herabeauty.ca/products/lurex-str-clip-9pcs | F19: 完全匹配 | G19: F4_27.jpg | H19: 完全 | J19: F4-27.jpg
A20: #F6/27 | B20: ROYAL IMEX | C20: 4 | D20: HAIR | E20: https://herabeauty.ca/products/lurex-str-clip-9pcs | F20: 完全匹配 | G20: F6_27.jpg | H20: 完全 | J20: F6-27.jpg
A21: #F6/613 | B21: ROYAL IMEX | C21: 2 | D21: HAIR | E21: https://herabeauty.ca/products/18-inch-clip-in-hair-extensions-royal-imex | F21: 完全匹配 | G21: F6_613.jpg | H21: 完全 | J21: F6-613.jpg
A22: #F8/10/16 | B22: ROYAL IMEX | C22: 1 | D22: HAIR | E22: https://herabeauty.ca/products/lurex-str-clip-9pcs | F22: 完全匹配 | G22: F8_10_16.jpg | H22: 完全 | J22: F8-10-16.jpg
A23: #F8/12/24 | B23: ROYAL IMEX | C23: 1 | D23: HAIR | E23: https://herabeauty.ca/products/18-inch-clip-in-hair-extensions-royal-imex | F23: 缺图 | H23: 最佳 58 | J23: F8-12-24.jpg
A24: #FS1B/30 | B24: ROYAL IMEX | C24: 19 | D24: BRAID/HAIR | E24: https://herabeauty.ca/products/royal-6x-3d-fc-tresse-40 | F24: 完全匹配 | G24: FS1B_30.jpg | H24: 完全 | J24: FS1B-30.jpg
A25: #FS27/30 | B25: ROYAL IMEX | C25: 5 | D25: HAIR/BRAID | E25: https://herabeauty.ca/products/royal-brz-body | F25: 缺图 | H25: 最佳 65 | I25: F27_4_30.jpg (60); F4_27_30.jpg (60); FS27_33.jpg (60) | J25: FS27-30.jpg
A26: #FS27/4/30 | B26: ROYAL IMEX | C26: 4 | D26: BRAID | E26: https://herabeauty.ca/products/royal-miracle-crochet-ocean | F26: 可能匹配 | G26: F27_4_30.jpg | H26: 缩写 87 | I26: F4_27_30.jpg (60); FS27_33.jpg (60); FS4_30.jpg (60) | J26: FS27-4-30.jpg
A27: #FS4/27/30 | B27: ROYAL IMEX | C27: 2 | D27: BRAID | E27: https://herabeauty.ca/products/french-curl-braid-hair-extensions-6x | F27: 完全匹配 | G27: fs4-27-30.jpeg | H27: 完全 | J27: FS4-27-30.jpeg
A28: #H.BLONDE | B28: ROYAL IMEX | C28: 1 | D28: BRAID | E28: https://herabeauty.ca/products/french-curl-braid-hair-extensions-6x | F28: 可能匹配 | G28: HONEY_BLONDE.jpg | H28: 缩写 83 | I28: ASH-BLONDE.jpg (74); FH1B_BLOND.jpg (60) | J28: H.BLONDE.jpg
A29: #H/BLONDE | B29: ROYAL IMEX | C29: 2 | D29: BRAID | E29: https://herabeauty.ca/products/passion-twist-crochet-hair-braid | F29: 可能匹配 | G29: HONEY_BLONDE.jpg | H29: 缩写 83 | I29: ASH-BLONDE.jpg (74); FH1B_BLOND.jpg (60) | J29: H-BLONDE.jpg
A30: #HONEY BLONDE | B30: ROYAL IMEX | C30: 2 | D30: BRAID | E30: https://herabeauty.ca/products/royal-imex-boho-curly-braid | F30: 完全匹配 | G30: HONEY_BLONDE.jpg | H30: 完全 | J30: HONEY BLONDE.jpg
A31: #NATURAL | B31: ROYAL IMEX | C31: 17 | D31: HAIR/BRAID | E31: https://herabeauty.ca/products/natural-dream-hawaii-wave | F31: 完全匹配 | G31: NATURAL.jpg | H31: 完全 | J31: NATURAL.jpg
A32: #NATURAL BLACK | B32: ROYAL IMEX | C32: 12 | D32: HAIR/BRAID | E32: https://herabeauty.ca/products/the-brazilian-4-x-5-hd-lace-closure-st-1 | F32: 完全匹配 | G32: NATURAL-BLACK.jpg | H32: 完全 | J32: NATURAL BLACK.jpg
A33: #SOM/27 | B33: ROYAL IMEX | C33: 3 | D33: BRAID | E33: https://herabeauty.ca/products/prestretched-braiding-hair-60-inch-royal-imex | F33: 完全匹配 | G33: SOM-27.jpg | H33: 完全 | J33: SOM-27.jpg
A34: #SOM/30 | B34: ROYAL IMEX | C34: 3 | D34: BRAID | E34: https://herabeauty.ca/products/prestretched-braiding-hair-60-inch-royal-imex | F34: 完全匹配 | G34: SOM-30.jpg | H34: 完全 | J34: SOM-30.jpg
A35: #SOM/BG | B35: ROYAL IMEX | C35: 5 | D35: BRAID | E35: https://herabeauty.ca/products/royal-imex-boho-curly-braid | F35: 可能匹配 | G35: SOM_BURG.jpg | H35: 逐段缩写 88 | J35: SOM-BG.jpg
A36: #SOM/BURG | B36: ROYAL IMEX | C36: 5 | D36: BRAID | E36: https://herabeauty.ca/products/royal-imex-water-wave-braid-20inch | F36: 完全匹配 | G36: SOM_BURG.jpg | H36: 完全 | J36: SOM-BURG.jpg
A37: #SOM/GREY | B37: ROYAL IMEX | C37: 3 | D37: BRAID | E37: https://herabeauty.ca/products/royal-imex-boho-curly-braid | F37: 完全匹配 | G37: SOM-GREY.jpg | H37: 完全 | J37: SOM-GREY.jpg
A38: #SOM27/30 | B38: ROYAL IMEX | C38: 13 | D38: BRAID/HAIR | E38: https://herabeauty.ca/products/royal-6x-3d-fc-tresse-40 | F38: 完全匹配 | G38: SOM-27_30.jpg | H38: 完全 | J38: SOM27-30.jpg
A39: #SOMRT27/30 | B39: ROYAL IMEX | C39: 2 | D39: HAIR | E39: https://herabeauty.ca/products/royal-nd-multi-passion-101214 | F39: 可能匹配 | G39: SOM-27_30.jpg | H39: 缩写 86 | J39: SOMRT27-30.jpg

Sheet Shake-n-go
A1: 色号 (variant name) | B1: Vendor | C1: 产品数 | D1: Type | E1: 示例产品 | F1: 状态 | G1: 匹配文件 | H1: 匹配方式/分数 | I1: 其他候选 | J1: 建议文件名 | K1: 确认后的文件（手填）
A2: #1 | B2: SHAKE N GO | C2: 101 | D2: BRAID/HAIR/WIG | E2: https://herabeauty.ca/products/freetress-french-curl-18-4x | F2: 完全匹配 | G2: 1.jpg | H2: 完全 | J2: 1.jpg
A3: #130 | B3: SHAKE N GO | C3: 2 | D3: HAIR/BRAID | E3: https://herabeauty.ca/products/spanish-curl-ponytail-extension-26-inch | F3: 完全匹配 | G3: 130.jpg | H3: 完全 | J3: 130.jpg
A4: #1B | B4: SHAKE N GO | C4: 101 | D4: BRAID/HAIR/WIG | E4: https://herabeauty.ca/products/freetress-french-curl-18-4x | F4: 完全匹配 | G4: 1B.jpg | H4: 完全 | J4: 1B.jpg
A5: #2 | B5: SHAKE N GO | C5: 96 | D5: BRAID/HAIR/WIG | E5: https://herabeauty.ca/products/freetress-french-curl-18-4x | F5: 完全匹配 | G5: 2.jpg | H5: 完全 | J5: 2.jpg
A6: #27 | B6: SHAKE N GO | C6: 18 | D6: BRAID/WIG | E6: https://herabeauty.ca/products/6x-freetress-aerolite-pre-stretched-braid-52 | F6: 完全匹配 | G6: 27.jpg | H6: 完全 | J6: 27.jpg
A7: #30 | B7: SHAKE N GO | C7: 25 | D7: BRAID/HAIR/WIG | E7: https://herabeauty.ca/products/freetress-french-curl-18-4x | F7: 完全匹配 | G7: 30.jpg | H7: 完全 | J7: 30.jpg
A8: #34 | B8: SHAKE N GO | C8: 1 | D8: WIG | E8: https://herabeauty.ca/products/golden-100-human-hair-hd-lace-front-wig-aisha | F8: 完全匹配 | G8: 34.jpg | H8: 完全 | J8: 34.jpg
A9: #3T1B/27/613 | B9: SHAKE N GO | C9: 1 | D9: BRAID | E9: https://herabeauty.ca/products/freetress-french-curl-braid-22-inch | F9: 完全匹配 | G9: 3T1B27613.jpg | H9: 完全 | J9: 3T1B-27-613.jpg
A10: #3T4/27/613 | B10: SHAKE N GO | C10: 2 | D10: BRAID | E10: https://herabeauty.ca/products/freetress-boho-mermaid-braid-24-inch | F10: 完全匹配 | G10: 3T427613.jpg | H10: 完全 | J10: 3T4-27-613.jpg
A11: #4 | B11: SHAKE N GO | C11: 70 | D11: BRAID/HAIR/WIG | E11: https://herabeauty.ca/products/freetress-french-curl-18-4x | F11: 完全匹配 | G11: 4.jpg | H11: 完全 | J11: 4.jpg
A12: #530 | B12: SHAKE N GO | C12: 14 | D12: HAIR/BRAID/WIG | E12: https://herabeauty.ca/products/organique-body-wave | F12: 完全匹配 | G12: 530.jpg | H12: 完全 | J12: 530.jpg
A13: #613 | B13: SHAKE N GO | C13: 5 | D13: HAIR/BRAID/WIG | E13: https://herabeauty.ca/products/organique-straight | F13: 完全匹配 | G13: 613.jpg | H13: 完全 | J13: 613.jpg
... A16: #BH HONEY | B16: SHAKE N GO | C16: 1 | D16: HAIR | E16: https://herabeauty.ca/products/organique-straight | F16: 完全匹配 | G16: BHHONEY.jpg | H16: 完全 | J16: BH HONEY.jpg
A17: #BLBK | B17: SHAKE N GO | C17: 1 | D17: WIG | E17: https://herabeauty.ca/products/freetress-equal-charlie-wig | F17: 可能匹配 | G17: BL.jpg | H17: 逐段缩写 88 | I17: TBLBK.jpg (76); DNBLBK.jpg (68); OPBLBK.jpg (68) | J17: BLBK.jpg
A18: #BLUE/CRUSH | B18: SHAKE N GO | C18: 1 | D18: BRAID | E18: https://herabeauty.ca/products/freetress-3x-braid-301-hair-extensions | F18: 完全匹配 | G18: BLUE-CRUSH.jpg | H18: 完全 | J18: BLUE-CRUSH.jpg
A19: #BROWN/ASH | B19: SHAKE N GO | C19: 1 | D19: BRAID | E19: https://herabeauty.ca/products/freetress-3x-braid-301-hair-extensions | F19: 完全匹配 | G19: BROWN-ASH.jpg | H19: 完全 | J19: BROWN-ASH.jpg
A20: #BURG | B20: SHAKE N GO | C20: 1 | D20: BRAID | E20: https://herabeauty.ca/products/freetress-braid-3x-pre-fluffed-poppintwist-16 | F20: 可能匹配 | G20: BG.jpg | H20: 逐段缩写 88 | I20: OMBURG.jpg (68); OTBURG.jpg (68) | J20: BURG.jpg
A21: #BURGUNDY | B21: SHAKE N GO | C21: 1 | D21: BRAID | E21: https://herabeauty.ca/products/freetress-braid-3x-poppin-twist-28 | F21: 可能匹配 | G21: BG.jpg | H21: 逐段缩写 88 | J21: BURGUNDY.jpg
A22: #CBGOLDBRN | B22: SHAKE N GO | C22: 1 | D22: BRAID | E22: https://herabeauty.ca/products/freetress-braid-3x-pre-fluffed-poppintwist-16 | F22: 完全匹配 | G22: CBGOLDBRN.jpg | H22: 完全 | J22: CBGOLDBRN.jpg
A23: #CHERRY | B23: SHAKE N GO | C23: 1 | D23: WIG | E23: https://herabeauty.ca/products/deep-waver-lace-front-wig-shake-n-go | F23: 可能匹配 | G23: CHERRYCOLA.jpg | H23: 逐段缩写 88 | I23: CHERRYWINE.jpg (88); HI-CHERRY.jpg (73); OTCHERRY.jpg (73) | J23: CHERRY.jpg
A24: #CHILLI | B24: SHAKE N GO | C24: 1 | D24: WIG | E24: https://herabeauty.ca/products/deep-waver-lace-front-wig-shake-n-go | F24: 缺图 | H24: 最佳 45 | J24: CHILLI.jpg
A25: #CMBERRY | B25: SHAKE N GO | C25: 1 | D25: WIG | E25: https://herabeauty.ca/products/freetress-equal-lite-003-wig | F25: 完全匹配 | G25: CMBERRY.jpg | H25: 完全 | J25: CMBERRY.jpg
A26: #CMBROWINIE | B26: SHAKE N GO | C26: 1 | D26: WIG | E26: https://herabeauty.ca/products/freetress-equal-lite-003-wig | F26: 可能匹配 | G26: CMBROWNIE.jpg | H26: 逐段缩写 88 | I26: HI-BROWNIE.jpg (63) | J26: CMBROWINIE.jpg
A27: #CMPECAN | B27: SHAKE N GO | C27: 1 | D27: WIG | E27: https://herabeauty.ca/products/freetress-equal-lite-003-wig | F27: 完全匹配 | G27: CMPECAN.jpg | H27: 完全 | J27: CMPECAN.jpg
A28: #CMRDCOPPER | B28: SHAKE N GO | C28: 1 | D28: WIG | E28: https://herabeauty.ca/products/freetress-equal-lite-003-wig | F28: 可能匹配 | G28: COPPER.jpg | H28: 逐段缩写 88 | I28: REDCOPPER.jpg (72); OMCOPPER.jpg (66); SRCOPPER.jpg (66) | J28: CMRDCOPPER.jpg
A29: #COPPER | B29: SHAKE N GO | C29: 3 | D29: BRAID | E29: https://herabeauty.ca/products/freetress-french-curl-18-4x | F29: 完全匹配 | G29: COPPER.jpg | H29: 完全 | J29: COPPER.jpg
A30: #DKPU | B30: SHAKE N GO | C30: 1 | D30: WIG | E30: https://herabeauty.ca/products/freetress-equal-charlie-wig | F30: 可能匹配 | G30: TDKPU.jpg | H30: 相似 76 | I30: OMDKPU.jpg (68); OPDKPU.jpg (68); OTDKPU.jpg (68) | J30: DKPU.jpg
A31: #ESPRESSO | B31: SHAKE N GO | C31: 3 | D31: HAIR | E31: https://herabeauty.ca/products/sleek-straight-ponytail-extension-secret-pocket | F31: 完全匹配 | G31: ESPRESSO.jpg | H31: 完全 | J31: ESPRESSO.jpg
A32: #F237 | B32: SHAKE N GO | C32: 1 | D32: WIG | E32: https://herabeauty.ca/products/freetress-creta-girl-half-wig | F32: 完全匹配 | G32: F237.jpg | H32: 完全 | J32: F237.jpg
A33: #F437 | B33: SHAKE N GO | C33: 1 | D33: WIG | E33: https://herabeauty.ca/products/freetress-creta-girl-half-wig | F33: 完全匹配 | G33: F437.jpg | H33: 完全 | J33: F437.jpg
A34: #FF1B27 | B34: SHAKE N GO | C34: 1 | D34: WIG | E34: https://herabeauty.ca/products/freetress-equal-5-inch-lace-part-wig | F34: 完全匹配 | G34: FF1B27.jpg | H34: 完全 | J34: FF1B27.jpg
A35: #FF30GD | B35: SHAKE N GO | C35: 1 | D35: WIG | E35: https://herabeauty.ca/products/freetress-equal-5-inch-lace-part-wig | F35: 可能匹配 | G35: F30.jpg | H35: 缩写 80 | J35: FF30GD.jpg
A36: #FF99J130 | B36: SHAKE N GO | C36: 1 | D36: WIG | E36: https://herabeauty.ca/products/freetress-equal-5-inch-lace-part-wig | F36: 缺图 | H36: 最佳 57 | J36: FF99J130.jpg
A37: #FF99J530 | B37: SHAKE N GO | C37: 2 | D37: WIG | E37: https://herabeauty.ca/products/freetress-equal-baby-hair-102 | F37: 缺图 | H37: 最佳 68 | I37: T99J530.jpg (68); OF99J530BG.jpg (66); OF99J530RD.jpg (66) | J37: FF99J530.jpg
A38: #FFCREAM | B38: SHAKE N GO | C38: 8 | D38: WIG | E38: https://herabeauty.ca/products/freetress-equal-valentino-lace-wig | F38: 缺图 | H38: 最佳 61 | J38: FFCREAM.jpg
A39: #FFGOLDBRN | B39: SHAKE N GO | C39: 7 | D39: WIG | E39: https://herabeauty.ca/products/freetress-equal-level-up-hd-lace-front-kamala | F39: 缺图 | H39: 最佳 66 | I39: GFFGOLDEN.jpg (66) | J39: FFGOLDBRN.jpg
A40: #FFH1B2430 | B40: SHAKE N GO | C40: 1 | D40: WIG | E40: https://herabeauty.ca/products/deep-waver-lace-front-wig-shake-n-go | F40: 缺图 | H40: 最佳 60 | I40: FF1B530.jpg (60); H1B2730.jpg (60) | J40: FFH1B2430.jpg
A41: #FFH1B99130 | B41: SHAKE N GO | C41: 1 | D41: WIG | E41: https://herabeauty.ca/products/deep-waver-lace-front-wig-shake-n-go | F41: 缺图 | H41: 最佳 60 | J41: FFH1B99130.jpg
A42: #FFH42726 | B42: SHAKE N GO | C42: 1 | D42: WIG | E42: https://herabeauty.ca/products/deep-waver-lace-front-wig-shake-n-go | F42: 缺图 | H42: 最佳 60 | J42: FFH42726.jpg
...

Sheet BOBBI BOSS
A1: 色号 (variant name) | B1: Vendor | C1: 产品数 | D1: Type | E1: 示例产品 | F1: 状态 | G1: 匹配文件 | H1: 匹配方式/分数 | I1: 其他候选 | J1: 建议文件名 | K1: 确认后的文件（手填）
A2: #1 | B2: BOBBI BOSS | C2: 14 | D2: WIG/HAIR/BRAID | E2: https://herabeauty.ca/products/boss-lace-13x5-hd-wig-luna | F2: 完全匹配 | G2: DARK/1.jpg | H2: 完全 | J2: 1.jpg
A3: #14/26A | B3: BOBBI BOSS | C3: 3 | D3: WIG | E3: https://herabeauty.ca/products/bobbi-boss-escara-lace-part-wig-b330-kendra | F3: 缺图 | H3: 最佳 53 | J3: 14-26A.jpg
A4: #1B | B4: BOBBI BOSS | C4: 16 | D4: WIG/HAIR/BRAID | E4: https://herabeauty.ca/products/boss-lace-13x5-hd-wig-luna | F4: 完全匹配 | G4: DARK/1B.jpg | H4: 完全 | J4: 1B.jpg
A5: #2 | B5: BOBBI BOSS | C5: 14 | D5: WIG/BRAID | E5: https://herabeauty.ca/products/boss-lace-13x5-hd-wig-luna | F5: 完全匹配 | G5: DARK/2.jpg | H5: 完全 | J5: 2.jpg
A6: #2/8F | B6: BOBBI BOSS | C6: 3 | D6: WIG | E6: https://herabeauty.ca/products/escara-deep-lace-part-wig-b380-linda | F6: 缺图 | H6: 最佳 53 | J6: 2-8F.jpg
A7: #3T4/YELLOW | B7: BOBBI BOSS | C7: 2 | D7: WIG | E7: https://herabeauty.ca/products/boss-lace-13x5-hd-wig-luna | F7: 缺图 | H7: 最佳 60 | I7: MIXED/TF2-YELLOW.jpg (60) | J7: 3T4-YELLOW.jpg
A8: #4 | B8: BOBBI BOSS | C8: 4 | D8: BRAID/WIG | E8: https://herabeauty.ca/products/distressed-butterfly-locs-18-inch-braid | F8: 完全匹配 | G8: DARK/4.jpg | H8: 完全 | J8: 4.jpg
A9: #4/22F | B9: BOBBI BOSS | C9: 1 | D9: WIG | E9: https://herabeauty.ca/products/bobbi-boss-escara-deep-part-lace-front-wig-b400-ariella | F9: 缺图 | H9: 最佳 64 | J9: 4-22F.jpg
A10: #44/51F | B10: BOBBI BOSS | C10: 1 | D10: WIG | E10: https://herabeauty.ca/products/bobbi-boss-escara-deep-part-lace-front-wig-b400-ariella | F10: 缺图 | H10: 最佳 46 | J10: 44-51F.jpg
A11: #6/12F | B11: BOBBI BOSS | C11: 1 | D11: WIG | E11: https://herabeauty.ca/products/bobbi-boss-escara-deep-part-lace-front-wig-b400-ariella | F11: 缺图 | H11: 最佳 53 | J11: 6-12F.jpg
A12: #6/8 | B12: BOBBI BOSS | C12: 2 | D12: WIG | E12: https://herabeauty.ca/products/escara-deep-lace-part-wig-b380-linda | F12: 缺图 | H12: 最佳 53 | J12: 6-8.jpg
A13: #6/812F | B13: BOBBI BOSS | C13: 3 | D13: WIG | E13: https://herabeauty.ca/products/escara-deep-lace-part-wig-b380-linda | F13: 缺图 | H13: 最佳 46 | J13: 6-812F.jpg
A14: #60 | B14: BOBBI BOSS | C14: 1 | D14: WIG | E14: https://herabeauty.ca/products/synthetic-lace-front-wig-escara-zoya | F14: 完全匹配 | G14: LIGHT/60.jpg | H14: 完全 | J14: 60.jpg
A15: #60W | B15: BOBBI BOSS | C15: 1 | D15: WIG | E15: https://herabeauty.ca/products/bobbi-boss-escara-deep-part-lace-front-wig-b400-ariella | F15: 完全匹配 | G15: LIGHT/60W.jpg | H15: 完全 | J15: 60W.jpg
A16: #613 | B16: BOBBI BOSS | C16: 4 | D16: WIG | E16: https://herabeauty.ca/products/synthetic-full-cap-wig-briarb | F16: 完全匹配 | G16: LIGHT/613.jpg | H16: 完全 | J16: 613.jpg
A17: #99J | B17: BOBBI BOSS | C17: 4 | D17: WIG/BRAID | E17: https://herabeauty.ca/products/escara-deep-lace-part-wig-b380-linda | F17: 完全匹配 | G17: MEDIUM/99J.jpg | H17: 完全 | J17: 99J.jpg
A18: #BLACK-CHER | B18: BOBBI BOSS | C18: 1 | D18: WIG | E18: https://herabeauty.ca/products/escara-full-cap-wig-b140-aria | F18: 完全匹配 | G18: DARK/BLACK-CHER.jpg | H18: 完全 | J18: BLACK-CHER.jpg
A19: #BTHL427613 | B19: BOBBI BOSS | C19: 1 | D19: WIG | E19: https://herabeauty.ca/products/lace-front-wig-brianne | F19: 缺图 | H19: 最佳 66 | I19: MIXED/TS4-27613.jpg (66); LIGHT/T27-613.jpg (60) | J19: BTHL427613.jpg
A20: #BTHL4306 | B20: BOBBI BOSS | C20: 1 | D20: WIG | E20: https://herabeauty.ca/products/bobbi-boss-patrice-lace-front-wig | F20: 缺图 | H20: 最佳 60 | J20: BTHL4306.jpg
A21: #BURGUNDY | B21: BOBBI BOSS | C21: 1 | D21: BRAID | E21: https://herabeauty.ca/products/bobbi-boss-nu-locs-18-inch-braids | F21: 可能匹配 | G21: MEDIUM/BUG.jpg | H21: 逐段缩写 88 | I21: MEDIUM/BURG.jpg (88) | J21: BURGUNDY.jpg
A22: #CAPPUCINO | B22: BOBBI BOSS | C22: 1 | D22: WIG | E22: https://herabeauty.ca/products/escara-full-cap-wig-b170-neena | F22: 缺图 | H22: 最佳 42 | J22: CAPPUCINO.jpg
A23: #CHOCO-FRST | B23: BOBBI BOSS | C23: 1 | D23: WIG | E23: https://herabeauty.ca/products/escara-full-cap-wig-b170-neena | F23: 缺图 | H23: 最佳 32 | J23: CHOCO-FRST.jpg
A24: #COCONUT-SPI | B24: BOBBI BOSS | C24: 2 | D24: WIG | E24: https://herabeauty.ca/products/escara-full-cap-wig-b320-christa | F24: 缺图 | H24: 最佳 42 | J24: COCONUT-SPI.jpg
A25: #D-CHOCO | B25: BOBBI BOSS | C25: 1 | D25: WIG | E25: https://herabeauty.ca/products/escara-full-cap-wig-b170-neena | F25: 缺图 | H25: 最佳 34 | J25: D-CHOCO.jpg
A26: #DX2216 | B26: BOBBI BOSS | C26: 1 | D26: WIG | E26: https://herabeauty.ca/products/synthetic-full-cap-wig-briarb | F26: 完全匹配 | G26: LIGHT/DX2216.jpg | H26: 完全 | J26: DX2216.jpg
A27: #EXPRESSO | B27: BOBBI BOSS | C27: 4 | D27: WIG | E27: https://herabeauty.ca/products/escara-full-cap-wig-b110-sapia | F27: 缺图 | H27: 最佳 38 | J27: EXPRESSO.jpg
A28: #F18/22 | B28: BOBBI BOSS | C28: 2 | D28: WIG | E28: https://herabeauty.ca/products/escara-deep-lace-part-wig-b380-linda | F28: 可能匹配 | G28: LIGHT/HF18-22.jpg | H28: 相似 77 | I28: LIGHT/18-22.jpg (76); MIXED/M18-22.jpg (68); MIXED/FL4-1822.jpg (60) | J28: F18-22.jpg
A29: #F1B/30 | B29: BOBBI BOSS | C29: 3 | D29: WIG | E29: https://herabeauty.ca/products/bobbi-boss-13x5-hd-lace-wig-melony | F29: 完全匹配 | G29: DARK/F1B-30.jpg | H29: 完全 | J29: F1B-30.jpg
A30: #F4/2730 | B30: BOBBI BOSS | C30: 1 | D30: WIG | E30: https://herabeauty.ca/products/bobbi-boss-5-deep-part-lace-front-wig-boss-lace-brielle | F30: 完全匹配 | G30: DARK/F4-2730.jpg | H30: 完全 | J30: F4-2730.jpg
A31: #F4/30 | B31: BOBBI BOSS | C31: 1 | D31: WIG | E31: https://herabeauty.ca/products/bobbi-boss-13x5-hd-lace-wig-melony | F31: 完全匹配 | G31: MEDIUM/F4-30.jpg | H31: 完全 | J31: F4-30.jpg
A32: #F613/27/10 | B32: BOBBI BOSS | C32: 1 | D32: WIG | E32: https://herabeauty.ca/products/premium-synthetic-full-wig-polina | F32: 缺图 | H32: 最佳 60 | I32: LIGHT/FS613-27.jpg (60) | J32: F613-27-10.jpg
A33: #FHL1B/27 | B33: BOBBI BOSS | C33: 1 | D33: WIG | E33: https://herabeauty.ca/products/bobbi-boss-100-unprocessed-human-hair-wet-and-wavy-wig-kalen | F33: 可能匹配 | G33: DARK/F1B-27.jpg | H33: 缩写 84 | I33: MIXED/HL1B-27.jpg (78); DARK/L1B-27.jpg (71); DARK/FS1B-27.jpg (65) | J33: FHL1B-27.jpg
A34: #FHL1B/30 | B34: BOBBI BOSS | C34: 1 | D34: WIG | E34: https://herabeauty.ca/products/bobbi-boss-100-unprocessed-human-hair-wet-and-wavy-wig-kalen | F34: 可能匹配 | G34: DARK/FL1B-30.jpg | H34: 缩写 87 | I34: DARK/F1B-30.jpg (84); MIXED/HL1B-30.jpg (78); SPECIAL/THL1B-30.jpg (73) | J34: FHL1B-30.jpg
A35: #FS1B/30 | B35: BOBBI BOSS | C35: 1 | D35: WIG | E35: https://herabeauty.ca/products/synthetic-full-cap-wig-briarb | F35: 完全匹配 | G35: DARK/FS1B-30.jpg | H35: 完全 | J35: FS1B-30.jpg
A36: #FS4/27/30 | B36: BOBBI BOSS | C36: 1 | D36: WIG | E36: https://herabeauty.ca/products/synthetic-full-cap-wig-briarb | F36: 完全匹配 | G36: DARK/FS4-2730.jpg | H36: 完全 | J36: FS4-27-30.jpg
A37: #GARNET-GLA | B37: BOBBI BOSS | C37: 1 | D37: WIG | E37: https://herabeauty.ca/products/escara-full-cap-wig-b140-aria | F37: 缺图 | H37: 最佳 42 | J37: GARNET-GLA.jpg
A38: #HARVST GLD | B38: BOBBI BOSS | C38: 1 | D38: WIG | E38: https://herabeauty.ca/products/escara-full-cap-wig-b250p-chelsea | F38: 缺图 | H38: 最佳 42 | J38: HARVST GLD.jpg
A39: #HL613/627 | B39: BOBBI BOSS | C39: 2 | D39: WIG | E39: https://herabeauty.ca/products/boss-lace-13x5-hd-wig-luna | F39: 缺图 | H39: 最佳 57 | J39: HL613-627.jpg
A40: #HLPURP/GRN | B40: BOBBI BOSS | C40: 1 | D40: WIG | E40: https://herabeauty.ca/products/boss-lace-13x5-hd-wig-luna | F40: 缺图 | H40: 最佳 50 | J40: HLPURP-GRN.jpg
...

Sheet 未使用的本地文件
A1: 库 | B1: 文件
A2: Outre | B2: 1_DRS_ORANGE_SANGRIA.jpg
A3: Outre | B3: 144.jpg
A4: Outre | B4: 1B_3DR_BLUE_SAPPHIRE.jpg
A5: Outre | B5: 1B_3DR_CHERRY_BOMB.jpg
A6: Outre | B6: 1B_3DR_FIRE_SUNSET.jpg
A7: Outre | B7: 1B_3DR_PINK_FUCHSIA.jpg
A8: Outre | B8: 1B_3DRFF_GALAXY_POP.jpg
A9: Outre | B9: 1B_3DRFF_PINK_CHERRY.jpg
A10: Outre | B10: 1B_BLUE SAPPHIRE.jpg
A11: Outre | B11: 1B_DRFF_BANANA_CREAM.jpg
A12: Outre | B12: 1B_DRFF_COPPER_FROST.jpg
... A3267: BOBBI BOSS | B3267: SPECIAL/TTVVORC.jpg
